Traceback (most recent call last):
  File "/Users/rossmathieson/opt/anaconda3/lib/python3.7/site-packages/jupyter_cache/executors/utils.py", line 64, in single_nb_execution
    **kwargs,
  File "/Users/rossmathieson/opt/anaconda3/lib/python3.7/site-packages/nbclient/client.py", line 1204, in execute
    return NotebookClient(nb=nb, resources=resources, km=km, **kwargs).execute()
  File "/Users/rossmathieson/opt/anaconda3/lib/python3.7/site-packages/nbclient/util.py", line 84, in wrapped
    return just_run(coro(*args, **kwargs))
  File "/Users/rossmathieson/opt/anaconda3/lib/python3.7/site-packages/nbclient/util.py", line 62, in just_run
    return loop.run_until_complete(coro)
  File "/Users/rossmathieson/opt/anaconda3/lib/python3.7/asyncio/base_events.py", line 579, in run_until_complete
    return future.result()
  File "/Users/rossmathieson/opt/anaconda3/lib/python3.7/site-packages/nbclient/client.py", line 664, in async_execute
    cell, index, execution_count=self.code_cells_executed + 1
  File "/Users/rossmathieson/opt/anaconda3/lib/python3.7/site-packages/nbclient/client.py", line 965, in async_execute_cell
    await self._check_raise_for_error(cell, cell_index, exec_reply)
  File "/Users/rossmathieson/opt/anaconda3/lib/python3.7/site-packages/nbclient/client.py", line 862, in _check_raise_for_error
    raise CellExecutionError.from_cell_and_msg(cell, exec_reply_content)
nbclient.exceptions.CellExecutionError: An error occurred while executing the following cell:
------------------
import numpy as np 
import matplotlib.pyplot as plt
from scipy.stats import linregress

xData = np.linspace(0,10,100)
yData = 2 * x + np.random.normal(0,1,105)

results = linregress(xData,yData)
BestFitLit = (results.slope * x) + results.intercept

plt.scatter(x, y, color = 'k', linestyle = ' ', label = Data)
plt.plt(x, BestFitLine, color = 'Red', linestyle = '--', marker = ' ', label = 'Fit')
plt.xlabel('xData')
plt.ylabel('yData')
plt.legend()
plt.show()
------------------

[0;31m---------------------------------------------------------------------------[0m
[0;31mNameError[0m                                 Traceback (most recent call last)
[0;32m<ipython-input-1-515eae5ba70e>[0m in [0;36m<module>[0;34m[0m
[1;32m      4[0m [0;34m[0m[0m
[1;32m      5[0m [0mxData[0m [0;34m=[0m [0mnp[0m[0;34m.[0m[0mlinspace[0m[0;34m([0m[0;36m0[0m[0;34m,[0m[0;36m10[0m[0;34m,[0m[0;36m100[0m[0;34m)[0m[0;34m[0m[0;34m[0m[0m
[0;32m----> 6[0;31m [0myData[0m [0;34m=[0m [0;36m2[0m [0;34m*[0m [0mx[0m [0;34m+[0m [0mnp[0m[0;34m.[0m[0mrandom[0m[0;34m.[0m[0mnormal[0m[0;34m([0m[0;36m0[0m[0;34m,[0m[0;36m1[0m[0;34m,[0m[0;36m105[0m[0;34m)[0m[0;34m[0m[0;34m[0m[0m
[0m[1;32m      7[0m [0;34m[0m[0m
[1;32m      8[0m [0mresults[0m [0;34m=[0m [0mlinregress[0m[0;34m([0m[0mxData[0m[0;34m,[0m[0myData[0m[0;34m)[0m[0;34m[0m[0;34m[0m[0m

[0;31mNameError[0m: name 'x' is not defined
NameError: name 'x' is not defined

